Watching for file changes with StatReloader
Watching for file changes with StatReloader
Watching for file changes with StatReloader
Watching for file changes with StatReloader
/home/kuma/movie_recommendation/movie/movieapp/views.py changed, reloading.
Watching for file changes with StatReloader
Watching for file changes with StatReloader
Starting new HTTPS connection (1): api.themoviedb.org:443
https://api.themoviedb.org:443 "GET /3/movie/popular?api_key=f56c4a60d742a43bd902a60a92b83cb3&page=1 HTTP/1.1" 200 None
Starting new HTTPS connection (1): api.themoviedb.org:443
https://api.themoviedb.org:443 "GET /3/genre/movie/list?api_key=f56c4a60d742a43bd902a60a92b83cb3 HTTP/1.1" 200 None
Queryset count: 20
Paginated response: count=20, next=None
Watching for file changes with StatReloader
Unauthorized: /api/movies/
Starting new HTTPS connection (1): api.themoviedb.org:443
https://api.themoviedb.org:443 "GET /3/movie/popular?api_key=f56c4a60d742a43bd902a60a92b83cb3&page=1 HTTP/1.1" 200 None
Starting new HTTPS connection (1): api.themoviedb.org:443
https://api.themoviedb.org:443 "GET /3/genre/movie/list?api_key=f56c4a60d742a43bd902a60a92b83cb3 HTTP/1.1" 200 None
Queryset count: 21
Paginated response: count=21, next=http://127.0.0.1:8000/api/movies/?page=2
Not Found: /api/favorite-movies/
Not Found: /api/favorite-movies/
Not Found: /api/favorite-movies/
Starting new HTTPS connection (1): api.themoviedb.org:443
https://api.themoviedb.org:443 "GET /3/movie/popular?api_key=f56c4a60d742a43bd902a60a92b83cb3&page=2 HTTP/1.1" 200 None
Starting new HTTPS connection (1): api.themoviedb.org:443
https://api.themoviedb.org:443 "GET /3/genre/movie/list?api_key=f56c4a60d742a43bd902a60a92b83cb3 HTTP/1.1" 200 None
Queryset count: 40
Paginated response: count=40, next=None
Not Found: /api/favorite-movies/
Not Found: /api/favorite-movies/
/home/kuma/movie_recommendation/movie/movieapp/views.py changed, reloading.
Watching for file changes with StatReloader
/home/kuma/movie_recommendation/movie/movieapp/views.py changed, reloading.
Watching for file changes with StatReloader
/home/kuma/movie_recommendation/movie/movieapp/urls.py changed, reloading.
Watching for file changes with StatReloader
Watching for file changes with StatReloader
Unauthorized: /api/favorite-movies/
FavoriteMovie queryset count: 0
Unauthorized: /api/favorite-movies/
Starting new HTTPS connection (1): api.themoviedb.org:443
https://api.themoviedb.org:443 "GET /3/movie/popular?api_key=f56c4a60d742a43bd902a60a92b83cb3&page=1 HTTP/1.1" 200 None
Starting new HTTPS connection (1): api.themoviedb.org:443
https://api.themoviedb.org:443 "GET /3/genre/movie/list?api_key=f56c4a60d742a43bd902a60a92b83cb3 HTTP/1.1" 200 None
Queryset count: 40
Paginated response: count=40, next=http://127.0.0.1:8000/api/movies/?page=2
Bad Request: /api/favorite-movies/
Bad Request: /api/favorite-movies/
Unauthorized: /api/favorite-movies/
Bad Request: /api/favorite-movies/
Unauthorized: /api/favorite-movies/
Starting new HTTPS connection (1): api.themoviedb.org:443
https://api.themoviedb.org:443 "GET /3/movie/popular?api_key=f56c4a60d742a43bd902a60a92b83cb3&page=1 HTTP/1.1" 200 None
Starting new HTTPS connection (1): api.themoviedb.org:443
https://api.themoviedb.org:443 "GET /3/genre/movie/list?api_key=f56c4a60d742a43bd902a60a92b83cb3 HTTP/1.1" 200 None
Queryset count: 41
Paginated response: count=41, next=http://127.0.0.1:8000/api/movies/?page=2
Unauthorized: /api/favorite-movies/
Bad Request: /api/favorite-movies/
Bad Request: /api/favorite-movies/
Bad Request: /api/favorite-movies/
Bad Request: /api/favorite-movies/
/home/kuma/movie_recommendation/movie/movieapp/serializers.py changed, reloading.
Watching for file changes with StatReloader
Unauthorized: /api/favorite-movies/
/home/kuma/movie_recommendation/movie/movieapp/serializers.py changed, reloading.
Watching for file changes with StatReloader
Unauthorized: /api/movies/
Starting new HTTPS connection (1): api.themoviedb.org:443
https://api.themoviedb.org:443 "GET /3/movie/popular?api_key=f56c4a60d742a43bd902a60a92b83cb3&page=1 HTTP/1.1" 200 None
Starting new HTTPS connection (1): api.themoviedb.org:443
https://api.themoviedb.org:443 "GET /3/genre/movie/list?api_key=f56c4a60d742a43bd902a60a92b83cb3 HTTP/1.1" 200 None
Queryset count: 41
Paginated response: count=41, next=http://127.0.0.1:8000/api/movies/?page=2
Bad Request: /api/favorite-movies/
FavoriteMovie queryset count: 0
Bad Request: /api/favorite-movies/
Bad Request: /api/favorite-movies/
Bad Request: /api/favorite-movies/
Bad Request: /api/favorite-movies/
Internal Server Error: /api/favorite-movies/
Traceback (most recent call last):
  File "/home/kuma/movie_recommendation/venv/lib/python3.10/site-packages/django/db/backends/utils.py", line 105, in _execute
    return self.cursor.execute(sql, params)
psycopg2.errors.UniqueViolation: duplicate key value violates unique constraint "movieapp_favoritemovie_user_id_movie_id_7ac0cdef_uniq"
DETAIL:  Key (user_id, movie_id)=(3, 1) already exists.


The above exception was the direct cause of the following exception:

Traceback (most recent call last):
  File "/home/kuma/movie_recommendation/venv/lib/python3.10/site-packages/django/core/handlers/exception.py", line 55, in inner
    response = get_response(request)
  File "/home/kuma/movie_recommendation/venv/lib/python3.10/site-packages/django/core/handlers/base.py", line 197, in _get_response
    response = wrapped_callback(request, *callback_args, **callback_kwargs)
  File "/home/kuma/movie_recommendation/venv/lib/python3.10/site-packages/django/views/decorators/csrf.py", line 65, in _view_wrapper
    return view_func(request, *args, **kwargs)
  File "/home/kuma/movie_recommendation/venv/lib/python3.10/site-packages/rest_framework/viewsets.py", line 124, in view
    return self.dispatch(request, *args, **kwargs)
  File "/home/kuma/movie_recommendation/venv/lib/python3.10/site-packages/rest_framework/views.py", line 509, in dispatch
    response = self.handle_exception(exc)
  File "/home/kuma/movie_recommendation/venv/lib/python3.10/site-packages/rest_framework/views.py", line 469, in handle_exception
    self.raise_uncaught_exception(exc)
  File "/home/kuma/movie_recommendation/venv/lib/python3.10/site-packages/rest_framework/views.py", line 480, in raise_uncaught_exception
    raise exc
  File "/home/kuma/movie_recommendation/venv/lib/python3.10/site-packages/rest_framework/views.py", line 506, in dispatch
    response = handler(request, *args, **kwargs)
  File "/home/kuma/movie_recommendation/venv/lib/python3.10/site-packages/rest_framework/mixins.py", line 19, in create
    self.perform_create(serializer)
  File "/home/kuma/movie_recommendation/movie/movieapp/views.py", line 118, in perform_create
    serializer.save(user=self.request.user)
  File "/home/kuma/movie_recommendation/venv/lib/python3.10/site-packages/rest_framework/serializers.py", line 208, in save
    self.instance = self.create(validated_data)
  File "/home/kuma/movie_recommendation/venv/lib/python3.10/site-packages/rest_framework/serializers.py", line 989, in create
    instance = ModelClass._default_manager.create(**validated_data)
  File "/home/kuma/movie_recommendation/venv/lib/python3.10/site-packages/django/db/models/manager.py", line 87, in manager_method
    return getattr(self.get_queryset(), name)(*args, **kwargs)
  File "/home/kuma/movie_recommendation/venv/lib/python3.10/site-packages/django/db/models/query.py", line 663, in create
    obj.save(force_insert=True, using=self.db)
  File "/home/kuma/movie_recommendation/venv/lib/python3.10/site-packages/django/db/models/base.py", line 902, in save
    self.save_base(
  File "/home/kuma/movie_recommendation/venv/lib/python3.10/site-packages/django/db/models/base.py", line 1008, in save_base
    updated = self._save_table(
  File "/home/kuma/movie_recommendation/venv/lib/python3.10/site-packages/django/db/models/base.py", line 1169, in _save_table
    results = self._do_insert(
  File "/home/kuma/movie_recommendation/venv/lib/python3.10/site-packages/django/db/models/base.py", line 1210, in _do_insert
    return manager._insert(
  File "/home/kuma/movie_recommendation/venv/lib/python3.10/site-packages/django/db/models/manager.py", line 87, in manager_method
    return getattr(self.get_queryset(), name)(*args, **kwargs)
  File "/home/kuma/movie_recommendation/venv/lib/python3.10/site-packages/django/db/models/query.py", line 1868, in _insert
    return query.get_compiler(using=using).execute_sql(returning_fields)
  File "/home/kuma/movie_recommendation/venv/lib/python3.10/site-packages/django/db/models/sql/compiler.py", line 1882, in execute_sql
    cursor.execute(sql, params)
  File "/home/kuma/movie_recommendation/venv/lib/python3.10/site-packages/django/db/backends/utils.py", line 122, in execute
    return super().execute(sql, params)
  File "/home/kuma/movie_recommendation/venv/lib/python3.10/site-packages/django/db/backends/utils.py", line 79, in execute
    return self._execute_with_wrappers(
  File "/home/kuma/movie_recommendation/venv/lib/python3.10/site-packages/django/db/backends/utils.py", line 92, in _execute_with_wrappers
    return executor(sql, params, many, context)
  File "/home/kuma/movie_recommendation/venv/lib/python3.10/site-packages/django/db/backends/utils.py", line 100, in _execute
    with self.db.wrap_database_errors:
  File "/home/kuma/movie_recommendation/venv/lib/python3.10/site-packages/django/db/utils.py", line 91, in __exit__
    raise dj_exc_value.with_traceback(traceback) from exc_value
  File "/home/kuma/movie_recommendation/venv/lib/python3.10/site-packages/django/db/backends/utils.py", line 105, in _execute
    return self.cursor.execute(sql, params)
django.db.utils.IntegrityError: duplicate key value violates unique constraint "movieapp_favoritemovie_user_id_movie_id_7ac0cdef_uniq"
DETAIL:  Key (user_id, movie_id)=(3, 1) already exists.

Internal Server Error: /api/favorite-movies/
Traceback (most recent call last):
  File "/home/kuma/movie_recommendation/venv/lib/python3.10/site-packages/django/db/backends/utils.py", line 105, in _execute
    return self.cursor.execute(sql, params)
psycopg2.errors.UniqueViolation: duplicate key value violates unique constraint "movieapp_favoritemovie_user_id_movie_id_7ac0cdef_uniq"
DETAIL:  Key (user_id, movie_id)=(3, 1) already exists.


The above exception was the direct cause of the following exception:

Traceback (most recent call last):
  File "/home/kuma/movie_recommendation/venv/lib/python3.10/site-packages/django/core/handlers/exception.py", line 55, in inner
    response = get_response(request)
  File "/home/kuma/movie_recommendation/venv/lib/python3.10/site-packages/django/core/handlers/base.py", line 197, in _get_response
    response = wrapped_callback(request, *callback_args, **callback_kwargs)
  File "/home/kuma/movie_recommendation/venv/lib/python3.10/site-packages/django/views/decorators/csrf.py", line 65, in _view_wrapper
    return view_func(request, *args, **kwargs)
  File "/home/kuma/movie_recommendation/venv/lib/python3.10/site-packages/rest_framework/viewsets.py", line 124, in view
    return self.dispatch(request, *args, **kwargs)
  File "/home/kuma/movie_recommendation/venv/lib/python3.10/site-packages/rest_framework/views.py", line 509, in dispatch
    response = self.handle_exception(exc)
  File "/home/kuma/movie_recommendation/venv/lib/python3.10/site-packages/rest_framework/views.py", line 469, in handle_exception
    self.raise_uncaught_exception(exc)
  File "/home/kuma/movie_recommendation/venv/lib/python3.10/site-packages/rest_framework/views.py", line 480, in raise_uncaught_exception
    raise exc
  File "/home/kuma/movie_recommendation/venv/lib/python3.10/site-packages/rest_framework/views.py", line 506, in dispatch
    response = handler(request, *args, **kwargs)
  File "/home/kuma/movie_recommendation/venv/lib/python3.10/site-packages/rest_framework/mixins.py", line 19, in create
    self.perform_create(serializer)
  File "/home/kuma/movie_recommendation/movie/movieapp/views.py", line 118, in perform_create
    serializer.save(user=self.request.user)
  File "/home/kuma/movie_recommendation/venv/lib/python3.10/site-packages/rest_framework/serializers.py", line 208, in save
    self.instance = self.create(validated_data)
  File "/home/kuma/movie_recommendation/venv/lib/python3.10/site-packages/rest_framework/serializers.py", line 989, in create
    instance = ModelClass._default_manager.create(**validated_data)
  File "/home/kuma/movie_recommendation/venv/lib/python3.10/site-packages/django/db/models/manager.py", line 87, in manager_method
    return getattr(self.get_queryset(), name)(*args, **kwargs)
  File "/home/kuma/movie_recommendation/venv/lib/python3.10/site-packages/django/db/models/query.py", line 663, in create
    obj.save(force_insert=True, using=self.db)
  File "/home/kuma/movie_recommendation/venv/lib/python3.10/site-packages/django/db/models/base.py", line 902, in save
    self.save_base(
  File "/home/kuma/movie_recommendation/venv/lib/python3.10/site-packages/django/db/models/base.py", line 1008, in save_base
    updated = self._save_table(
  File "/home/kuma/movie_recommendation/venv/lib/python3.10/site-packages/django/db/models/base.py", line 1169, in _save_table
    results = self._do_insert(
  File "/home/kuma/movie_recommendation/venv/lib/python3.10/site-packages/django/db/models/base.py", line 1210, in _do_insert
    return manager._insert(
  File "/home/kuma/movie_recommendation/venv/lib/python3.10/site-packages/django/db/models/manager.py", line 87, in manager_method
    return getattr(self.get_queryset(), name)(*args, **kwargs)
  File "/home/kuma/movie_recommendation/venv/lib/python3.10/site-packages/django/db/models/query.py", line 1868, in _insert
    return query.get_compiler(using=using).execute_sql(returning_fields)
  File "/home/kuma/movie_recommendation/venv/lib/python3.10/site-packages/django/db/models/sql/compiler.py", line 1882, in execute_sql
    cursor.execute(sql, params)
  File "/home/kuma/movie_recommendation/venv/lib/python3.10/site-packages/django/db/backends/utils.py", line 122, in execute
    return super().execute(sql, params)
  File "/home/kuma/movie_recommendation/venv/lib/python3.10/site-packages/django/db/backends/utils.py", line 79, in execute
    return self._execute_with_wrappers(
  File "/home/kuma/movie_recommendation/venv/lib/python3.10/site-packages/django/db/backends/utils.py", line 92, in _execute_with_wrappers
    return executor(sql, params, many, context)
  File "/home/kuma/movie_recommendation/venv/lib/python3.10/site-packages/django/db/backends/utils.py", line 100, in _execute
    with self.db.wrap_database_errors:
  File "/home/kuma/movie_recommendation/venv/lib/python3.10/site-packages/django/db/utils.py", line 91, in __exit__
    raise dj_exc_value.with_traceback(traceback) from exc_value
  File "/home/kuma/movie_recommendation/venv/lib/python3.10/site-packages/django/db/backends/utils.py", line 105, in _execute
    return self.cursor.execute(sql, params)
django.db.utils.IntegrityError: duplicate key value violates unique constraint "movieapp_favoritemovie_user_id_movie_id_7ac0cdef_uniq"
DETAIL:  Key (user_id, movie_id)=(3, 1) already exists.

/home/kuma/movie_recommendation/movie/movieapp/serializers.py changed, reloading.
Watching for file changes with StatReloader
Watching for file changes with StatReloader
Unauthorized: /api/favorite-movies/
FavoriteMovie queryset count: 1
FavoriteMovie paginated response: count=1, next=None
Starting new HTTPS connection (1): api.themoviedb.org:443
https://api.themoviedb.org:443 "GET /3/movie/popular?api_key=f56c4a60d742a43bd902a60a92b83cb3&page=1 HTTP/1.1" 200 None
Starting new HTTPS connection (1): api.themoviedb.org:443
https://api.themoviedb.org:443 "GET /3/genre/movie/list?api_key=f56c4a60d742a43bd902a60a92b83cb3 HTTP/1.1" 200 None
Queryset count: 41
Paginated response: count=41, next=http://127.0.0.1:8000/api/movies/?page=2
Bad Request: /api/favorite-movies/
/home/kuma/movie_recommendation/movie/movieapp/serializers.py changed, reloading.
Watching for file changes with StatReloader
Watching for file changes with StatReloader
Unauthorized: /api/favorite-movies/
FavoriteMovie queryset count: 7
FavoriteMovie paginated response: count=7, next=None
Starting new HTTPS connection (1): api.themoviedb.org:443
https://api.themoviedb.org:443 "GET /3/movie/popular?api_key=f56c4a60d742a43bd902a60a92b83cb3&page=1 HTTP/1.1" 200 None
Starting new HTTPS connection (1): api.themoviedb.org:443
https://api.themoviedb.org:443 "GET /3/genre/movie/list?api_key=f56c4a60d742a43bd902a60a92b83cb3 HTTP/1.1" 200 None
Queryset count: 41
Paginated response: count=41, next=http://127.0.0.1:8000/api/movies/?page=2
Bad Request: /api/favorite-movies/
Not Found: /api/favorite-movies/10/
Not Found: /api/favorite-movies/9/
Not Found: /api/favorite-movies/8/
Not Found: /api/favorite-movies/10/
Not Found: /api/favorite-movies/10/
Not Found: /api/favorite-movies/10/
Not Found: /api/favorite-movies/10/
Not Found: /api/favorite-movies/11/
Not Found: /api/favorite-movies/11/
Not Found: /api/favorite-movies/9/
